Workbook

Sheet PIVOT TABLE
B3: Row Labels | C3: Sum of No.Of.Working Days | D3: Sum of EXTRA DAYS (Holiday) | E3: Sum of CTC
B4: PICKER / PACKER | C4: 92 | D4: 9 | E4: 52141.963
B5: SUPERVISOR | C5: 22 | D5: 2 | E5: 14427.205
B6: Grand Total | C6: 114 | D6: 11 | E6: 66569.167
E8: =GETPIVOTDATA("Sum of CTC",$B$3)-#REF! -> #REF!
B10: Row Labels | C10: Sum of No.Of.Working Days | D10: Sum of EXTRA DAYS (Holiday) | E10: Sum of CTC
B11: PICKER / PACKER | C11: 158 | D11: 0 | E11: 91497.35
B12: SUPERVISOR | C12: 29 | D12: 0 | E12: 19378.847
B13: Grand Total | C13: 187 | D13: 0 | E13: 110876.2
E15: =GETPIVOTDATA("Sum of CTC",$B$10)-'Wage Sheet'!AS21 -> -130218.49

Sheet Payslips 
A1: SNO | B1: ID NO. | C1: BANK ACCOUNT NUMBER | D1: MODE OF PAYMENT | E1: PF NO | F1: UAN NO | G1: ESIC No | H1: EMPLOYEE | I1: DOJ | J1: Design. | K1: Total P. Days | L1: No. of Days Wrkd | M1: EXTRA DAYS | N1: OT Hrs | O1: OT Amt | P1: BASIC + VDA | Q1: HRA | R1: Other Allownce | S1: BONUS | T1: LEAVE WAGES | U1: GROSS AMT | V1: PF (12%) | W1: ESI (0.75%) | X1: P.Tax | Y1: Others | Z1: NET PAY | AA1: LWF | AB1: Total DD | AC1: Other Addings | AD1: TOTAL NET PAY | AE1: IN WORDS
A2: =#REF! -> #REF! | B2: =#REF! -> #REF! | C2: 20230356319 | D2: ONLINE | E2: GRVSP19631980000017295 | F2: 101732547031 | G2: 3313172073 | H2: =#REF! -> #REF! | I2: 05-02-2024 | J2: =#REF! -> #REF! | K2: =#REF! -> #REF! | L2: =#REF! -> #REF! | M2: =#REF! -> #REF! | N2: =#REF! -> #REF! | O2: =#REF! -> #REF! | P2: =#REF! -> #REF! | Q2: =#REF! -> #REF! | R2: =0 -> 0 | S2: =#REF! -> #REF! | T2: =#REF! -> #REF! | U2: =#REF! -> #REF! | V2: =#REF! -> #REF! | W2: =#REF! -> #REF! | X2: =#REF! -> #REF! | Y2: =#REF! -> #REF! | Z2: =#REF! -> #REF! | AA2: 3 | AB2: =V2+W2+X2+Y2+AA2 -> #REF! | AC2: =#REF! -> #REF! | AD2: =#REF! -> #REF! | AE2: =[1]!rswords(AD2) -> #NAME?
A3: =#REF! -> #REF! | B3: =#REF! -> #REF! | C3: 8548101004924 | D3: ONLINE | E3: GRVSP19631980000017293 | F3: 101822613065 | G3: 7011527196 | H3: =#REF! -> #REF! | I3: 05-02-2024 | J3: =#REF! -> #REF! | K3: =#REF! -> #REF! | L3: =#REF! -> #REF! | M3: =#REF! -> #REF! | N3: =#REF! -> #REF! | O3: =#REF! -> #REF! | P3: =#REF! -> #REF! | Q3: =#REF! -> #REF! | R3: =0 -> 0 | S3: =#REF! -> #REF! | T3: =#REF! -> #REF! | U3: =#REF! -> #REF! | V3: =#REF! -> #REF! | W3: =#REF! -> #REF! | X3: =#REF! -> #REF! | Y3: =#REF! -> #REF! | Z3: =#REF! -> #REF! | AA3: 3 | AB3: =V3+W3+X3+Y3+AA3 -> #REF! | AC3: =#REF! -> #REF! | AD3: =#REF! -> #REF! | AE3: =[1]!rswords(AD3) -> #NAME?
A4: =#REF! -> #REF! | B4: =#REF! -> #REF! | C4: 32694861473 | D4: ONLINE | E4: GRVSP19631980000017289 | F4: 101468118332 | G4: 7011527210 | H4: =#REF! -> #REF! | I4: 05-02-2024 | J4: =#REF! -> #REF! | K4: =#REF! -> #REF! | L4: =#REF! -> #REF! | M4: =#REF! -> #REF! | N4: =#REF! -> #REF! | O4: =#REF! -> #REF! | P4: =#REF! -> #REF! | Q4: =#REF! -> #REF! | R4: =0 -> 0 | S4: =#REF! -> #REF! | T4: =#REF! -> #REF! | U4: =#REF! -> #REF! | V4: =#REF! -> #REF! | W4: =#REF! -> #REF! | X4: =#REF! -> #REF! | Y4: =#REF! -> #REF! | Z4: =#REF! -> #REF! | AA4: 3 | AB4: =V4+W4+X4+Y4+AA4 -> #REF! | AC4: =#REF! -> #REF! | AD4: =#REF! -> #REF! | AE4: =[1]!rswords(AD4) -> #NAME?
A5: =#REF! -> #REF! | B5: =#REF! -> #REF! | C5: 40082954282 | D5: ONLINE | E5: GRVSP19631980000017296 | F5: 101810090779 | G5: 7011527230 | H5: =#REF! -> #REF! | I5: 05-02-2024 | J5: =#REF! -> #REF! | K5: =#REF! -> #REF! | L5: =#REF! -> #REF! | M5: =#REF! -> #REF! | N5: =#REF! -> #REF! | O5: =#REF! -> #REF! | P5: =#REF! -> #REF! | Q5: =#REF! -> #REF! | R5: =0 -> 0 | S5: =#REF! -> #REF! | T5: =#REF! -> #REF! | U5: =#REF! -> #REF! | V5: =#REF! -> #REF! | W5: =#REF! -> #REF! | X5: =#REF! -> #REF! | Y5: =#REF! -> #REF! | Z5: =#REF! -> #REF! | AA5: 3 | AB5: =V5+W5+X5+Y5+AA5 -> #REF! | AC5: =#REF! -> #REF! | AD5: =#REF! -> #REF! | AE5: =[1]!rswords(AD5) -> #NAME?
A6: =#REF! -> #REF! | B6: =#REF! -> #REF! | C6: 43134295833 | D6: ONLINE | E6: GRVSP19631980000017789 | F6: 102100945894 | G6: 7011636702 | H6: =#REF! -> #REF! | I6: 12-07-2024 | J6: =#REF! -> #REF! | K6: =#REF! -> #REF! | L6: =#REF! -> #REF! | M6: =#REF! -> #REF! | N6: =#REF! -> #REF! | O6: =#REF! -> #REF! | P6: =#REF! -> #REF! | Q6: =#REF! -> #REF! | R6: =0 -> 0 | S6: =#REF! -> #REF! | T6: =#REF! -> #REF! | U6: =#REF! -> #REF! | V6: =#REF! -> #REF! | W6: =#REF! -> #REF! | X6: =#REF! -> #REF! | Y6: =#REF! -> #REF! | Z6: =#REF! -> #REF! | AA6: 3 | AB6: =V6+W6+X6+Y6+AA6 -> #REF! | AC6: =#REF! -> #REF! | AD6: =#REF! -> #REF! | AE6: =[1]!rswords(AD6) -> #NAME?
A7: =#REF! -> #REF! | B7: =#REF! -> #REF! | C7: 8548108001851 | D7: ONLINE | E7: GRVSP19631980000017871 | F7: 101649730069 | G7: 7011625666 | H7: =#REF! -> #REF! | I7: 01-08-2024 | J7: =#REF! -> #REF! | K7: =#REF! -> #REF! | L7: =#REF! -> #REF! | M7: =#REF! -> #REF! | N7: =#REF! -> #REF! | O7: =#REF! -> #REF! | P7: =#REF! -> #REF! | Q7: =#REF! -> #REF! | R7: =0 -> 0 | S7: =#REF! -> #REF! | T7: =#REF! -> #REF! | U7: =#REF! -> #REF! | V7: =#REF! -> #REF! | W7: =#REF! -> #REF! | X7: =#REF! -> #REF! | Y7: =#REF! -> #REF! | Z7: =#REF! -> #REF! | AA7: 3 | AB7: =V7+W7+X7+Y7+AA7 -> #REF! | AC7: =#REF! -> #REF! | AD7: =#REF! -> #REF! | AE7: =[1]!rswords(AD7) -> #NAME?
A8: =#REF! -> #REF! | B8: =#REF! -> #REF! | C8: 62393501778 | D8: ONLINE | E8: GRVSP19631980000017917 | F8: 101757115388 | G8: 7011652412 | H8: =#REF! -> #REF! | I8: 20-09-2024 | J8: =#REF! -> #REF! | K8: =#REF! -> #REF! | L8: =#REF! -> #REF! | M8: =#REF! -> #REF! | N8: =#REF! -> #REF! | O8: =#REF! -> #REF! | P8: =#REF! -> #REF! | Q8: =#REF! -> #REF! | R8: =0 -> 0 | S8: =#REF! -> #REF! | T8: =#REF! -> #REF! | U8: =#REF! -> #REF! | V8: =#REF! -> #REF! | W8: =#REF! -> #REF! | X8: =#REF! -> #REF! | Y8: =#REF! -> #REF! | Z8: =#REF! -> #REF! | AA8: 3 | AB8: =V8+W8+X8+Y8+AA8 -> #REF! | AC8: =#REF! -> #REF! | AD8: =#REF! -> #REF! | AE8: =[1]!rswords(AD8) -> #NAME?
A9: =#REF! -> #REF! | B9: =#REF! -> #REF! | C9: 8548101005753 | D9: ONLINE | E9: GRVSP19631980000017949 | F9: 101819300534 | G9: 7011664787 | H9: =#REF! -> #REF! | I9: 22.09.2024 | J9: =#REF! -> #REF! | K9: =#REF! -> #REF! | L9: =#REF! -> #REF! | M9: =#REF! -> #REF! | N9: =#REF! -> #REF! | O9: =#REF! -> #REF! | P9: =#REF! -> #REF! | Q9: =#REF! -> #REF! | R9: =0 -> 0 | S9: =#REF! -> #REF! | T9: =#REF! -> #REF! | U9: =#REF! -> #REF! | V9: =#REF! -> #REF! | W9: =#REF! -> #REF! | X9: =#REF! -> #REF! | Y9: =#REF! -> #REF! | Z9: =#REF! -> #REF! | AA9: 3 | AB9: =V9+W9+X9+Y9+AA9 -> #REF! | AC9: =#REF! -> #REF! | AD9: =#REF! -> #REF! | AE9: =[1]!rswords(AD9) -> #NAME?
A10: =#REF! -> #REF! | B10: =#REF! -> #REF! | C10: 42104140868 | D10: ONLINE | E10: GRVSP19631980000017948 | F10: 101870727875 | G10: 7011664791 | H10: =#REF! -> #REF! | I10: 02.10.2024 | J10: =#REF! -> #REF! | K10: =#REF! -> #REF! | L10: =#REF! -> #REF! | M10: =#REF! -> #REF! | N10: =#REF! -> #REF! | O10: =#REF! -> #REF! | P10: =#REF! -> #REF! | Q10: =#REF! -> #REF! | R10: =0 -> 0 | S10: =#REF! -> #REF! | T10: =#REF! -> #REF! | U10: =#REF! -> #REF! | V10: =#REF! -> #REF! | W10: =#REF! -> #REF! | X10: =#REF! -> #REF! | Y10: =#REF! -> #REF! | Z10: =#REF! -> #REF! | AA10: 3 | AB10: =V10+W10+X10+Y10+AA10 -> #REF! | AC10: =#REF! -> #REF! | AD10: =#REF! -> #REF! | AE10: =[1]!rswords(AD10) -> #NAME?
A11: ='Left Employee'!A50 -> 9 | B11: ='Left Employee'!B50 -> SGS/RIL/NLR-FC/0011 | C11: 42398161315 | D11: ONLINE | E11: GRVSP19631980000018094 | F11: 101832305575 | G11: 7011707530 | H11: ='Left Employee'!D50 -> K.BRAMAIAH | I11: 27.01.2025 | J11: ='Left Employee'!N50 -> PICKER / PACKER | K11: ='Left Employee'!P50 -> 28 | L11: ='Left Employee'!Q50 -> 3 | M11: ='Left Employee'!R50 -> 0 | N11: ='Left Employee'!S50 -> 0 | O11: ='Left Employee'!AJ50 -> 0 | P11: ='Left Employee'!AE50 -> 1343 | Q11: ='Left Employee'!AF50 -> 30 | R11: =0 -> 0 | S11: ='Left Employee'!AK50 -> 112 | T11: ='Left Employee'!AI50 -> 168 | U11: ='Left Employee'!AL50 -> 1653 | V11: ='Left Employee'!AV50 -> 161 | W11: ='Left Employee'!AW50 -> 13 | X11: ='Left Employee'!AY50 -> 0 | Y11: ='Left Employee'!BH50 -> 0 | Z11: ='Left Employee'!BA50 -> 1477 | AA11: 3 | AB11: =V11+W11+X11+Y11+AA11 -> 177 | AC11: ='Left Employee'!AM50 -> 0 | AD11: ='Left Employee'!BI50 -> 1477 | AE11: =[1]!rswords(AD11) -> #NAME?
A12: ='Left Employee'!A51 -> 10 | B12: ='Left Employee'!B51 -> SGS/RIL/NLR-FC/0010 | C12: 33426073618 | D12: ONLINE | E12: GRVSP19631980000017918 | F12: 102123677383 | G12: 7011652406 | H12: ='Left Employee'!D51 -> SYAM KUMAR | I12: 24-08-2024 | J12: ='Left Employee'!N51 -> PICKER / PACKER | K12: ='Left Employee'!P51 -> 28 | L12: ='Left Employee'!Q51 -> 28 | M12: ='Left Employee'!R51 -> 0 | N12: ='Left Employee'!S51 -> 0 | O12: ='Left Employee'!AJ51 -> 0 | P12: ='Left Employee'!AE51 -> 12531 | Q12: ='Left Employee'!AF51 -> 281 | R12: =0 -> 0 | S12: ='Left Employee'!AK51 -> 1044 | T12: ='Left Employee'!AI51 -> 1566 | U12: ='Left Employee'!AL51 -> 15422 | V12: ='Left Employee'!AV51 -> 1504 | W12: ='Left Employee'!AW51 -> 116 | X12: ='Left Employee'!AY51 -> 150 | Y12: ='Left Employee'!BH51 -> 0 | Z12: ='Left Employee'!BA51 -> 13650 | AA12: 3 | AB12: =V12+W12+X12+Y12+AA12 -> 1773 | AC12: ='Left Employee'!AM51 -> 0 | AD12: ='Left Employee'!BI51 -> 13650 | AE12: =[1]!rswords(AD12) -> #NAME?
A13: =#REF! -> #REF! | B13: =#REF! -> #REF! | C13: 20179714615 | D13: ONLINE | E13: GRVSP19631980000018167 | F13: 101857380459 | G13: 3314289361 | H13: =#REF! -> #REF! | I13: 06.02.2025 | J13: =#REF! -> #REF! | K13: =#REF! -> #REF! | L13: =#REF! -> #REF! | M13: =#REF! -> #REF! | N13: =#REF! -> #REF! | O13: =#REF! -> #REF! | P13: =#REF! -> #REF! | Q13: =#REF! -> #REF! | R13: =0 -> 0 | S13: =#REF! -> #REF! | T13: =#REF! -> #REF! | U13: =#REF! -> #REF! | V13: =#REF! -> #REF! | W13: =#REF! -> #REF! | X13: =#REF! -> #REF! | Y13: =#REF! -> #REF! | Z13: =#REF! -> #REF! | AA13: 3 | AB13: =V13+W13+X13+Y13+AA13 -> #REF! | AC13: =#REF! -> #REF! | AD13: =#REF! -> #REF! | AE13: =[1]!rswords(AD13) -> #NAME?
A14: =#REF! -> #REF! | B14: =#REF! -> #REF! | C14: 34546652759 | D14: ONLINE | E14: GRVSP19631980000018216 | F14: 101820670152 | G14: 3313972243 | H14: =#REF! -> #REF! | I14: 06.02.2025 | J14: =#REF! -> #REF! | K14: =#REF! -> #REF! | L14: =#REF! -> #REF! | M14: =#REF! -> #REF! | N14: =#REF! -> #REF! | O14: =#REF! -> #REF! | P14: =#REF! -> #REF! | Q14: =#REF! -> #REF! | R14: =0 -> 0 | S14: =#REF! -> #REF! | T14: =#REF! -> #REF! | U14: =#REF! -> #REF! | V14: =#REF! -> #REF! | W14: =#REF! -> #REF! | X14: =#REF! -> #REF! | Y14: =#REF! -> #REF! | Z14: =#REF! -> #REF! | AA14: 3 | AB14: =V14+W14+X14+Y14+AA14 -> #REF! | AC14: =#REF! -> #REF! | AD14: =#REF! -> #REF! | AE14: =[1]!rswords(AD14) -> #NAME?
A15: =#REF! -> #REF! | B15: =#REF! -> #REF! | C15: 20290204659 | D15: ONLINE | E15: GRVSP19631980000018169 | F15: 101779348599 | G15: 3313573567 | H15: =#REF! -> #REF! | I15: 10.02.2025 | J15: =#REF! -> #REF! | K15: =#REF! -> #REF! | L15: =#REF! -> #REF! | M15: =#REF! -> #REF! | N15: =#REF! -> #REF! | O15: =#REF! -> #REF! | P15: =#REF! -> #REF! | Q15: =#REF! -> #REF! | R15: =0 -> 0 | S15: =#REF! -> #REF! | T15: =#REF! -> #REF! | U15: =#REF! -> #REF! | V15: =#REF! -> #REF! | W15: =#REF! -> #REF! | X15: =#REF! -> #REF! | Y15: =#REF! -> #REF! | Z15: =#REF! -> #REF! | AA15: 3 | AB15: =V15+W15+X15+Y15+AA15 -> #REF! | AC15: =#REF! -> #REF! | AD15: =#REF! -> #REF! | AE15: =[1]!rswords(AD15) -> #NAME?

Sheet Attendence
C1: Month | D1: 46054
A2: S NO | B2: EMP CODE | C2: NAME | D2: Gender | E2: Store Code | F2: DAte of Joining | G2: =+D1 -> 46054 | H2: =+G2+1 -> 46055 | I2: =+H2+1 -> 46056 | J2: =+I2+1 -> 46057 | K2: =+J2+1 -> 46058 | L2: =+K2+1 -> 46059 | M2: =+L2+1 -> 46060 | N2: =+M2+1 -> 46061 | O2: =+N2+1 -> 46062 | ... AH2: =+AG2+1 -> 46081 | AI2: Present Days | AJ2: Absent | AK2: Week Offs | AL2: TotAl DAys | AM2: Public HolidAys | AN2: TLLP
G3: =TEXT(G2,"DDD") -> Sun | H3: =TEXT(H2,"DDD") -> Mon | I3: =TEXT(I2,"DDD") -> Tue | J3: =TEXT(J2,"DDD") -> Wed | K3: =TEXT(K2,"DDD") -> Thu | L3: =TEXT(L2,"DDD") -> Fri | M3: =TEXT(M2,"DDD") -> Sat | N3: =TEXT(N2,"DDD") -> Sun | ... AH3: =TEXT(AH2,"DDD") -> Sat
A4: 1 | B4: PPRR01063774 | C4: C SUVARNA LAXMI | D4: FEMALE | E4: TL4P | F4: 45887 | G4: P | H4: P | I4: P | J4: P | K4: W/O | L4: P | M4: A | N4: A | O4: A | P4: A | Q4: A | R4: A | S4: A | T4: A | U4: A | V4: A | W4: A | X4: A | Y4: A | Z4: A | AA4: A | AB4: A | AC4: A | AD4: A | AE4: A | AF4: A | AG4: A | AH4: A | AI4: =COUNTIF(G4:AH4,"P")+COUNTIF(G4:AH4,"PPH") -> 5 | AJ4: =COUNTIF(G4:AH4,"A") -> 0 | AK4: =COUNTIF(G4:AH4,"W/O") -> 1 | AL4: =+AI4+AK4 -> 6 | AM4: =COUNTIF(G4:AH4,"PPH")+COUNTIF(G4:AH4,"PH") -> 0 | AN4: =AI4+AM4 -> 5
A5: 2 | B5: PPRR01063695 | C5: G LAVANYA | D5: FEMALE | E5: TL4P | F5: 45887 | G5: P | H5: W/O | I5: P | J5: P | K5: P | L5: P | M5: P | N5: P | O5: P | P5: P | Q5: P | R5: P | S5: P | T5: P | U5: P | V5: PPH | W5: P | X5: P | Y5: P | Z5: P | AA5: A | AB5: A | AC5: A | AD5: A | AE5: A | AF5: A | AG5: A | AH5: A | AI5: =COUNTIF(G5:AH5,"P")+COUNTIF(G5:AH5,"PPH") -> 19 | AJ5: =COUNTIF(G5:AH5,"A") -> 0 | AK5: =COUNTIF(G5:AH5,"W/O") -> 1 | AL5: =+AI5+AK5 -> 20 | AM5: =COUNTIF(G5:AH5,"PPH")+COUNTIF(G5:AH5,"PH") -> 1 | AN5: =AI5+AM5 -> 20
A6: 3 | B6: PPRR01063947 | C6: J RAHELU | D6: MALE | E6: TL4P | F6: 20.08.2025 | G6: P | H6: P | I6: P | J6: W/O | K6: P | L6: P | M6: P | N6: P | O6: P | P6: P | Q6: P | R6: P | S6: P | T6: P | U6: P | V6: PPH | W6: P | X6: P | Y6: P | Z6: P | AA6: P | AB6: P | AC6: P | AD6: P | AE6: P | AF6: P | AG6: W/O | AH6: P | AI6: =COUNTIF(G6:AH6,"P")+COUNTIF(G6:AH6,"PPH") -> 26 | AJ6: =COUNTIF(G6:AH6,"A") -> 0 | AK6: =COUNTIF(G6:AH6,"W/O") -> 2 | AL6: =+AI6+AK6 -> 28 | AM6: =COUNTIF(G6:AH6,"PPH")+COUNTIF(G6:AH6,"PH") -> 1 | AN6: =AI6+AM6 -> 27
A7: 4 | B7: PPRR01064005 | C7: J SUNITHA | D7: FEMALE | E7: TL4P | F7: 23.08.2025 | G7: P | H7: P | I7: P | J7: P | K7: W/O | L7: P | M7: P | N7: P | O7: P | P7: P | Q7: P | R7: P | S7: P | T7: P | U7: P | V7: PPH | W7: P | X7: P | Y7: W/O | Z7: P | AA7: P | AB7: P | AC7: P | AD7: P | AE7: P | AF7: P | AG7: P | AH7: P | AI7: =COUNTIF(G7:AH7,"P")+COUNTIF(G7:AH7,"PPH") -> 26 | AJ7: =COUNTIF(G7:AH7,"A") -> 0 | AK7: =COUNTIF(G7:AH7,"W/O") -> 2 | AL7: =+AI7+AK7 -> 28 | AM7: =COUNTIF(G7:AH7,"PPH")+COUNTIF(G7:AH7,"PH") -> 1 | AN7: =AI7+AM7 -> 27
A8: 5 | B8: PPRR01063737 | C8: K DURGA SHYAMALA | D8: FEMALE | E8: TL4P | F8: 45887 | G8: P | H8: P | I8: P | J8: P | K8: P | L8: P | M8: P | N8: W/O | O8: P | P8: P | Q8: W/O | R8: P | S8: P | T8: P | U8: P | V8: PPH | W8: P | X8: P | Y8: P | Z8: P | AA8: P | AB8: P | AC8: P | AD8: P | AE8: P | AF8: P | AG8: W/O | AH8: P | AI8: =COUNTIF(G8:AH8,"P")+COUNTIF(G8:AH8,"PPH") -> 25 | AJ8: =COUNTIF(G8:AH8,"A") -> 0 | AK8: =COUNTIF(G8:AH8,"W/O") -> 3 | AL8: =+AI8+AK8 -> 28 | AM8: =COUNTIF(G8:AH8,"PPH")+COUNTIF(G8:AH8,"PH") -> 1 | AN8: =AI8+AM8 -> 26
A9: 6 | B9: PPRR01063671 | C9: K.VENKATA LAXMI | D9: FEMALE | E9: TL4P | F9: 18.09.2025 | G9: P | H9: P | I9: P | J9: W/O | K9: P | L9: P | M9: P | N9: P | O9: P | P9: P | Q9: P | R9: P | S9: P | T9: P | U9: P | V9: PPH | W9: P | X9: P | Y9: P | Z9: P | AA9: P | AB9: P | AC9: W/O | AD9: P | AE9: P | AF9: P | AG9: P | AH9: P | AI9: =COUNTIF(G9:AH9,"P")+COUNTIF(G9:AH9,"PPH") -> 26 | AJ9: =COUNTIF(G9:AH9,"A") -> 0 | AK9: =COUNTIF(G9:AH9,"W/O") -> 2 | AL9: =+AI9+AK9 -> 28 | AM9: =COUNTIF(G9:AH9,"PPH")+COUNTIF(G9:AH9,"PH") -> 1 | AN9: =AI9+AM9 -> 27
A10: 7 | B10: PPRR01063685 | C10: M ANURADHA | D10: FEMALE | E10: TL4P | F10: 45887 | G10: P | H10: P | I10: P | J10: P | K10: P | L10: P | M10: P | N10: P | O10: P | P10: P | Q10: P | R10: P | S10: P | T10: W/O | U10: P | V10: PPH | W10: P | X10: P | Y10: P | Z10: P | AA10: P | AB10: P | AC10: P | AD10: P | AE10: P | AF10: W/O | AG10: P | AH10: P | AI10: =COUNTIF(G10:AH10,"P")+COUNTIF(G10:AH10,"PPH") -> 26 | AJ10: =COUNTIF(G10:AH10,"A") -> 0 | AK10: =COUNTIF(G10:AH10,"W/O") -> 2 | AL10: =+AI10+AK10 -> 28 | AM10: =COUNTIF(G10:AH10,"PPH")+COUNTIF(G10:AH10,"PH") -> 1 | AN10: =AI10+AM10 -> 27
A11: 8 | B11: PPRR01064021 | C11: O.ANITHA DEVI | D11: FEMALE | E11: TL4P | F11: 26.08.2025 | G11: P | H11: P | I11: W/O | J11: P | K11: P | L11: P | M11: P | N11: P | O11: P | P11: P | Q11: P | R11: P | S11: P | T11: P | U11: P | V11: PPH | W11: P | X11: P | Y11: P | Z11: P | AA11: A | AB11: A | AC11: A | AD11: A | AE11: A | AF11: A | AG11: A | AH11: A | AI11: =COUNTIF(G11:AH11,"P")+COUNTIF(G11:AH11,"PPH") -> 19 | AJ11: =COUNTIF(G11:AH11,"A") -> 0 | AK11: =COUNTIF(G11:AH11,"W/O") -> 1 | AL11: =+AI11+AK11 -> 20 | AM11: =COUNTIF(G11:AH11,"PPH")+COUNTIF(G11:AH11,"PH") -> 1 | AN11: =AI11+AM11 -> 20
A12: 9 | B12: PPRR01086837 | C12: CH SUJATHA | D12: FEMALE | E12: TL4P | F12: 01.09.2025 | G12: P | H12: P | I12: P | J12: P | K12: P | L12: W/O | M12: P | N12: P | O12: P | P12: P | Q12: P | R12: P | S12: P | T12: P | U12: P | V12: PPH | W12: P | X12: P | Y12: P | Z12: P | AA12: P | AB12: P | AC12: P | AD12: P | AE12: P | AF12: P | AG12: P | AH12: P | AI12: =COUNTIF(G12:AH12,"P")+COUNTIF(G12:AH12,"PPH") -> 27 | AJ12: =COUNTIF(G12:AH12,"A") -> 0 | AK12: =COUNTIF(G12:AH12,"W/O") -> 1 | AL12: =+AI12+AK12 -> 28 | AM12: =COUNTIF(G12:AH12,"PPH")+COUNTIF(G12:AH12,"PH") -> 1 | AN12: =AI12+AM12 -> 28
A13: 10 | B13: PPRR01064055 | C13: J SAI KUMAR | D13: MALE | E13: TL4P | F13: 15.08.2025 | G13: P | H13: P | I13: P | J13: P | K13: P | L13: W/O | M13: P | N13: P | O13: P | P13: P | Q13: W/O | R13: P | S13: P | T13: P | U13: P | V13: PPH | W13: W/O | X13: P | Y13: P | Z13: P | AA13: P | AB13: P | AC13: P | AD13: P | AE13: W/O | AF13: P | AG13: P | AH13: P | AI13: =COUNTIF(G13:AH13,"P")+COUNTIF(G13:AH13,"PPH") -> 24 | AJ13: =COUNTIF(G13:AH13,"A") -> 0 | AK13: =COUNTIF(G13:AH13,"W/O") -> 4 | AL13: =+AI13+AK13 -> 28 | AM13: =COUNTIF(G13:AH13,"PPH")+COUNTIF(G13:AH13,"PH") -> 1 | AN13: =AI13+AM13 -> 25
A14: 11 | B14: PPRR01063977 | C14: P.RAMA RAO | D14: MALE | E14: TL4P | F14: 21.08.2025 | G14: P | H14: P | I14: P | J14: P | K14: P | L14: P | M14: P | N14: P | O14: P | P14: P | Q14: P | R14: W/O | S14: P | T14: P | U14: P | V14: PPH | W14: P | X14: P | Y14: P | Z14: P | AA14: W/O | AB14: P | AC14: P | AD14: P | AE14: P | AF14: P | AG14: P | AH14: P | AI14: =COUNTIF(G14:AH14,"P")+COUNTIF(G14:AH14,"PPH") -> 26 | AJ14: =COUNTIF(G14:AH14,"A") -> 0 | AK14: =COUNTIF(G14:AH14,"W/O") -> 2 | AL14: =+AI14+AK14 -> 28 | AM14: =COUNTIF(G14:AH14,"PPH")+COUNTIF(G14:AH14,"PH") -> 1 | AN14: =AI14+AM14 -> 27
A15: 12 | B15: PPRR01063660 | C15: P.SAI SURENDRA BHANU | D15: MALE | E15: TL4P | F15: 45884 | G15: P | H15: P | I15: P | J15: W/O | K15: P | L15: P | M15: P | N15: P | O15: P | P15: P | Q15: P | R15: P | S15: P | T15: P | U15: P | V15: PPH | W15: P | X15: P | Y15: P | Z15: P | AA15: P | AB15: P | AC15: P | AD15: P | AE15: P | AF15: W/O | AG15: P | AH15: P | AI15: =COUNTIF(G15:AH15,"P")+COUNTIF(G15:AH15,"PPH") -> 26 | AJ15: =COUNTIF(G15:AH15,"A") -> 0 | AK15: =COUNTIF(G15:AH15,"W/O") -> 2 | AL15: =+AI15+AK15 -> 28 | AM15: =COUNTIF(G15:AH15,"PPH")+COUNTIF(G15:AH15,"PH") -> 1 | AN15: =AI15+AM15 -> 27
A16: 13 | B16: PPRR01086793 | C16: VAMSI | D16: MALE | E16: TL4P | F16: 08.09.2025 | G16: W/O | H16: P | I16: P | J16: P | K16: P | L16: P | M16: P | N16: P | O16: W/O | P16: P | Q16: P | R16: P | S16: P | T16: P | U16: P | V16: PPH | W16: P | X16: P | Y16: P | Z16: P | AA16: W/O | AB16: P | AC16: P | AD16: P | AE16: P | AF16: P | AG16: P | AH16: P | AI16: =COUNTIF(G16:AH16,"P")+COUNTIF(G16:AH16,"PPH") -> 25 | AJ16: =COUNTIF(G16:AH16,"A") -> 0 | AK16: =COUNTIF(G16:AH16,"W/O") -> 3 | AL16: =+AI16+AK16 -> 28 | AM16: =COUNTIF(G16:AH16,"PPH")+COUNTIF(G16:AH16,"PH") -> 1 | AN16: =AI16+AM16 -> 26
A17: 14 | B17: PPRR01086755 | C17: KUMAR | D17: MALE | E17: TL4P | F17: 08.09.2025 | G17: P | H17: P | I17: W/O | J17: P | K17: P | L17: P | M17: P | N17: P | O17: P | P17: W/O | Q17: P | R17: P | S17: P | T17: P | U17: P | V17: PPH | W17: P | X17: P | Y17: P | Z17: P | AA17: P | AB17: P | AC17: P | AD17: P | AE17: P | AF17: P | AG17: P | AH17: P | AI17: =COUNTIF(G17:AH17,"P")+COUNTIF(G17:AH17,"PPH") -> 26 | AJ17: =COUNTIF(G17:AH17,"A") -> 0 | AK17: =COUNTIF(G17:AH17,"W/O") -> 2 | AL17: =+AI17+AK17 -> 28 | AM17: =COUNTIF(G17:AH17,"PPH")+COUNTIF(G17:AH17,"PH") -> 1 | AN17: =AI17+AM17 -> 27
A18: 15 | B18: PPRR01063438 | C18: K CHANDRA KALAVATHI | D18: FEMALE | E18: TL4P | F18: 45884 | G18: A | H18: A | I18: A | J18: A | K18: A | L18: A | M18: A | N18: A | O18: A | P18: A | Q18: A | R18: P | S18: P | T18: P | U18: P | V18: PPH | W18: P | X18: P | Y18: W/O | Z18: P | AA18: P | AB18: A | AC18: P | AD18: P | AE18: P | AF18: P | AG18: P | AH18: P | AI18: =COUNTIF(G18:AH18,"P")+COUNTIF(G18:AH18,"PPH") -> 15 | AJ18: =COUNTIF(G18:AH18,"A") -> 0 | AK18: =COUNTIF(G18:AH18,"W/O") -> 1 | AL18: =+AI18+AK18 -> 16 | AM18: =COUNTIF(G18:AH18,"PPH")+COUNTIF(G18:AH18,"PH") -> 1 | AN18: =AI18+AM18 -> 16
AI19: =SUM(AI4:AI18) -> 341 | AJ19: =SUM(AJ4:AJ18) -> 0 | AK19: =SUM(AK4:AK18) -> 29 | AL19: =SUM(AL4:AL18) -> 370 | AM19: =SUM(AM4:AM18) -> 14 | AN19: =SUM(AN4:AN18) -> 355

Sheet Wage Sheet
A1: TECHNO SOLUTIONS
A2: WAGE SHEET FOR THE MONTH OF 1ST FEB '26 TO 28TH FEB '26
A3: ANAKAPALLI-TL4P | BI3: UNIFORM | BQ3: SHOE
A4: Sr. No | B4: Emp code Number ( as allotted by the currnet vendor ) | C4: SCRUM ID | D4: Name as per Attendance | E4: Name of Employee (As Per AADHAR) | F4: Gender | G4: UAN NUMBER | H4: ESIC NUMBER | I4: DOJ (MM.DD.YYYY) | J4: Location | K4: Region | L4: State | M4: Designation | N4: Skill Type | O4: Month | P4: No.of days | Q4: No.Of.Working Days | R4: OT Hrs | S4: Basic | T4: DA | U4: Consolidated Basic/PF Wages | V4: HRA | W4: Other Allownce | X4: Conveyance | Y4: Leave (If payable Monthly) | Z4: Bonus (If payable Monthly) | AA4: Gross Per Month | AB4: Basic | AC4: DA | AD4: Consolidated Basic/PF Wages | AE4: HRA | AF4: Other Allownce | AG4: Conveyance | AH4: Leave (If payable Monthly) | AI4: OT Amount | AJ4: Bonus (If payable Monthly) | AK4: Gross Per Month | AL4: EPF Salary | AM4: PF - 13% | AN4: ESIC - 3.25% | AO4: Employer LWF | AP4: Total Indirects | AQ4: Co Controlling | AR4: Uniform Charges | AS4: CTC | AT4: PF - 12% | AU4: ESIC - 0.75% | AV4: Employee LWF | AW4: PT | AX4: Total Deduction | AY4: Take Home | BA4: Name of the Acccount Holder | BB4: A/C No. | BC4: IFSC Code | BD4: Take Home | BE4: Damages | BF4: Salary Payable | BG4: Remarks | BI4: Uniform (Apron/T-Shirt) | BJ4: Colour (Maroon / Sea Green) | BK4: Gender | BL4: Size (S, M, L, XL, XXL) | BM4: Required Quantity | BN4: Issued Quantity | BO4: Balance Quantity | BP4: Date of Issue | BQ4: Size (6,7,8,9,10) | BR4: Required Pairs | BS4: Issued Pairs | BT4: Required Pairs | BU4: Date of Issue | BV4: ID cards | BW4: Issue date | BX4: Appoint letter | BY4: Issue date
A5: 1 | C5: PPRR01063774 | D5: C SUVARNA LAXMI | E5: CHANDAKA SUVARNA LAXMI | F5: FEMALE | G5: 101742491826 | H5: 7011080364 | I5: 45887 | J5: ANAKAPALLI | K5: South | L5: Andhra Pradesh | M5: PICKER / PACKER | N5: SemiSkilled | O5: 46054 | P5: 26 | Q5: 5 | R5: 0 | S5: 12813 | T5: 0 | U5: =S5+T5 -> 12813 | V5: 0 | W5: 0 | X5: 0 | Y5: 1602 | Z5: 1067 | AA5: =SUM(U5:Z5) -> 15482 | AB5: =ROUND(S5/P5*Q5,0) -> 2464 | AC5: =ROUND(T5/P5*Q5,0) -> 0 | AD5: =AB5+AC5 -> 2464 | AE5: =ROUND(V5/P5*Q5,0) -> 0 | AF5: =ROUND(W5/P5*Q5,0) -> 0 | AG5: =ROUND(X5/P5*Q5,0) -> 0 | AH5: =ROUND(Y5/P5*Q5,0) -> 308 | AI5: =ROUND((S5/26)/4*R5,0) -> 0 | AJ5: =ROUND(Z5/P5*Q5,0) -> 205 | AK5: =ROUND(SUM(AD5:AJ5),0) -> 2977 | AL5: =IF(AB5<15000,AB5,15000) -> 2464 | AM5: =ROUND(AL5*13%,0) -> 320 | AN5: =IF(AA5>=21000,0,AK5*3.25%) -> 96.7525 | AO5: 5.83 | AP5: =SUM(AM5:AO5) -> 422.5825 | AQ5: =AK5+AP5 -> 3399.5825 | AS5: =AQ5+AR5 -> 3399.5825 | AT5: =ROUND(AL5*12%,0) -> 296 | AU5: =IF(AA5>21000,0,CEILING(AK5*0.75%,1)) -> 23 | AV5: 2.5 | AW5: =IF(AK5>20000,200,IF(AK5>15000,150,0)) -> 0 | AX5: =SUM(AT5:AW5) -> 321.5 | AY5: =ROUND(AK5-AX5,0) -> 2656 | BA5: CHANDAKA SUVARNA LAXMI | BB5: 20204187170 | BC5: SBIN0003135 | BD5: =AY5 -> 2656 | BF5: =ROUND(BD5-BE5,0) -> 2656
A6: 2 | C6: PPRR01063695 | D6: G LAVANYA | E6: GOVAADA LAVANYA | F6: FEMALE | G6: 101973885037 | H6: 6210707847 | I6: 45887 | J6: ANAKAPALLI | K6: South | L6: Andhra Pradesh | M6: PICKER / PACKER | N6: SemiSkilled | O6: 46054 | P6: 26 | Q6: 20 | R6: 0 | S6: 12813 | T6: 0 | U6: =S6+T6 -> 12813 | V6: 0 | W6: 0 | X6: 0 | Y6: 1602 | Z6: 1067 | AA6: =SUM(U6:Z6) -> 15482 | AB6: =ROUND(S6/P6*Q6,0) -> 9856 | AC6: =ROUND(T6/P6*Q6,0) -> 0 | AD6: =AB6+AC6 -> 9856 | AE6: =ROUND(V6/P6*Q6,0) -> 0 | AF6: =ROUND(W6/P6*Q6,0) -> 0 | AG6: =ROUND(X6/P6*Q6,0) -> 0 | AH6: =ROUND(Y6/P6*Q6,0) -> 1232 | AI6: =ROUND((S6/26)/4*R6,0) -> 0 | AJ6: =ROUND(Z6/P6*Q6,0) -> 821 | AK6: =ROUND(SUM(AD6:AJ6),0) -> 11909 | AL6: =IF(AB6<15000,AB6,15000) -> 9856 | AM6: =ROUND(AL6*13%,0) -> 1281 | AN6: =IF(AA6>=21000,0,AK6*3.25%) -> 387.0425 | AO6: 5.83 | AP6: =SUM(AM6:AO6) -> 1673.8725 | AQ6: =AK6+AP6 -> 13582.872 | AS6: =AQ6+AR6 -> 13582.872 | AT6: =ROUND(AL6*12%,0) -> 1183 | AU6: =IF(AA6>21000,0,CEILING(AK6*0.75%,1)) -> 90 | AV6: 2.5 | AW6: =IF(AK6>20000,200,IF(AK6>15000,150,0)) -> 0 | AX6: =SUM(AT6:AW6) -> 1275.5 | AY6: =ROUND(AK6-AX6,0) -> 10634 | BA6: GOVAADA LAVANYA | BB6: 33429301407 | BC6: SBIN0003135 | BD6: =AY6 -> 10634 | BF6: =ROUND(BD6-BE6,0) -> 10634
A7: 3 | C7: PPRR01063947 | D7: J RAHELU | E7: JAJULA SALOMI RAHELU | F7: FEMALE | G7: 102241169775 | H7: 6210708919 | I7: 45889 | J7: ANAKAPALLI | K7: South | L7: Andhra Pradesh | M7: PICKER / PACKER | N7: SemiSkilled | O7: 46054 | P7: 26 | Q7: 27 | R7: 0 | S7: 12813 | T7: 0 | U7: =S7+T7 -> 12813 | V7: 0 | W7: 0 | X7: 0 | Y7: 1602 | Z7: 1067 | AA7: =SUM(U7:Z7) -> 15482 | AB7: =ROUND(S7/P7*Q7,0) -> 13306 | AC7: =ROUND(T7/P7*Q7,0) -> 0 | AD7: =AB7+AC7 -> 13306 | AE7: =ROUND(V7/P7*Q7,0) -> 0 | AF7: =ROUND(W7/P7*Q7,0) -> 0 | AG7: =ROUND(X7/P7*Q7,0) -> 0 | AH7: =ROUND(Y7/P7*Q7,0) -> 1664 | AI7: =ROUND((S7/26)/4*R7,0) -> 0 | AJ7: =ROUND(Z7/P7*Q7,0) -> 1108 | AK7: =ROUND(SUM(AD7:AJ7),0) -> 16078 | AL7: =IF(AB7<15000,AB7,15000) -> 13306 | AM7: =ROUND(AL7*13%,0) -> 1730 | AN7: =IF(AA7>=21000,0,AK7*3.25%) -> 522.535 | AO7: 5.83 | AP7: =SUM(AM7:AO7) -> 2258.365 | AQ7: =AK7+AP7 -> 18336.365 | AS7: =AQ7+AR7 -> 18336.365 | AT7: =ROUND(AL7*12%,0) -> 1597 | AU7: =IF(AA7>21000,0,CEILING(AK7*0.75%,1)) -> 121 | AV7: 2.5 | AW7: =IF(AK7>20000,200,IF(AK7>15000,150,0)) -> 150 | AX7: =SUM(AT7:AW7) -> 1870.5 | AY7: =ROUND(AK7-AX7,0) -> 14208 | BA7: JAJULA SALOMI RAHELU | BB7: 44424894089 | BC7: SBIN0000805 | BD7: =AY7 -> 14208 | BF7: =ROUND(BD7-BE7,0) -> 14208
A8: 4 | C8: PPRR01064005 | D8: J SUNITHA | E8: JERRIPOTHULA SUNEETHA | F8: MALE | G8: 101381848135 | H8: 7010490592 | I8: 45892 | J8: ANAKAPALLI | K8: South | L8: Andhra Pradesh | M8: PICKER / PACKER | N8: SemiSkilled | O8: 46054 | P8: 26 | Q8: 27 | R8: 0 | S8: 12813 | T8: 0 | U8: =S8+T8 -> 12813 | V8: 0 | W8: 0 | X8: 0 | Y8: 1602 | Z8: 1067 | AA8: =SUM(U8:Z8) -> 15482 | AB8: =ROUND(S8/P8*Q8,0) -> 13306 | AC8: =ROUND(T8/P8*Q8,0) -> 0 | AD8: =AB8+AC8 -> 13306 | AE8: =ROUND(V8/P8*Q8,0) -> 0 | AF8: =ROUND(W8/P8*Q8,0) -> 0 | AG8: =ROUND(X8/P8*Q8,0) -> 0 | AH8: =ROUND(Y8/P8*Q8,0) -> 1664 | AI8: =ROUND((S8/26)/4*R8,0) -> 0 | AJ8: =ROUND(Z8/P8*Q8,0) -> 1108 | AK8: =ROUND(SUM(AD8:AJ8),0) -> 16078 | AL8: =IF(AB8<15000,AB8,15000) -> 13306 | AM8: =ROUND(AL8*13%,0) -> 1730 | AN8: =IF(AA8>=21000,0,AK8*3.25%) -> 522.535 | AO8: 5.83 | AP8: =SUM(AM8:AO8) -> 2258.365 | AQ8: =AK8+AP8 -> 18336.365 | AS8: =AQ8+AR8 -> 18336.365 | AT8: =ROUND(AL8*12%,0) -> 1597 | AU8: =IF(AA8>21000,0,CEILING(AK8*0.75%,1)) -> 121 | AV8: 2.5 | AW8: =IF(AK8>20000,200,IF(AK8>15000,150,0)) -> 150 | AX8: =SUM(AT8:AW8) -> 1870.5 | AY8: =ROUND(AK8-AX8,0) -> 14208 | BA8: JERRIPOTHULA SUNEETHA | BB8: 20177167594 | BC8: SBIN0015402 | BD8: =AY8 -> 14208 | BF8: =ROUND(BD8-BE8,0) -> 14208
A9: 5 | C9: PPRR01063737 | D9: K DURGA SHYAMALA | E9: KOSURU DURGA SYAMALA | F9: FEMALE | G9: 101974395762 | H9: 6210707942 | I9: 45887 | J9: ANAKAPALLI | K9: South | L9: Andhra Pradesh | M9: PICKER / PACKER | N9: SemiSkilled | O9: 46054 | P9: 26 | Q9: 26 | R9: 0 | S9: 12813 | T9: 0 | U9: =S9+T9 -> 12813 | V9: 0 | W9: 0 | X9: 0 | Y9: 1602 | Z9: 1067 | AA9: =SUM(U9:Z9) -> 15482 | AB9: =ROUND(S9/P9*Q9,0) -> 12813 | AC9: =ROUND(T9/P9*Q9,0) -> 0 | AD9: =AB9+AC9 -> 12813 | AE9: =ROUND(V9/P9*Q9,0) -> 0 | AF9: =ROUND(W9/P9*Q9,0) -> 0 | AG9: =ROUND(X9/P9*Q9,0) -> 0 | AH9: =ROUND(Y9/P9*Q9,0) -> 1602 | AI9: =ROUND((S9/26)/4*R9,0) -> 0 | AJ9: =ROUND(Z9/P9*Q9,0) -> 1067 | AK9: =ROUND(SUM(AD9:AJ9),0) -> 15482 | AL9: =IF(AB9<15000,AB9,15000) -> 12813 | AM9: =ROUND(AL9*13%,0) -> 1666 | AN9: =IF(AA9>=21000,0,AK9*3.25%) -> 503.165 | AO9: 5.83 | AP9: =SUM(AM9:AO9) -> 2174.995 | AQ9: =AK9+AP9 -> 17656.995 | AS9: =AQ9+AR9 -> 17656.995 | AT9: =ROUND(AL9*12%,0) -> 1538 | AU9: =IF(AA9>21000,0,CEILING(AK9*0.75%,1)) -> 117 | AV9: 2.5 | AW9: =IF(AK9>20000,200,IF(AK9>15000,150,0)) -> 150 | AX9: =SUM(AT9:AW9) -> 1807.5 | AY9: =ROUND(AK9-AX9,0) -> 13675 | BA9: KOSURU DURGA SYAMALA | BB9: 32048025423 | BC9: SBIN0011112 | BD9: =AY9 -> 13675 | BF9: =ROUND(BD9-BE9,0) -> 13675
A10: 6 | C10: PPRR01063671 | D10: K VENKATA LAXMI | E10: KAMADENU VENKATA LAXMI | F10: FEMALE | G10: 102240254040 | H10: 6210707436 | I10: 45887 | J10: ANAKAPALLI | K10: South | L10: Andhra Pradesh | M10: PICKER / PACKER | N10: SemiSkilled | O10: 46054 | P10: 26 | Q10: 27 | R10: 0 | S10: 12813 | T10: 0 | U10: =S10+T10 -> 12813 | V10: 0 | W10: 0 | X10: 0 | Y10: 1602 | Z10: 1067 | AA10: =SUM(U10:Z10) -> 15482 | AB10: =ROUND(S10/P10*Q10,0) -> 13306 | AC10: =ROUND(T10/P10*Q10,0) -> 0 | AD10: =AB10+AC10 -> 13306 | AE10: =ROUND(V10/P10*Q10,0) -> 0 | AF10: =ROUND(W10/P10*Q10,0) -> 0 | AG10: =ROUND(X10/P10*Q10,0) -> 0 | AH10: =ROUND(Y10/P10*Q10,0) -> 1664 | AI10: =ROUND((S10/26)/4*R10,0) -> 0 | AJ10: =ROUND(Z10/P10*Q10,0) -> 1108 | AK10: =ROUND(SUM(AD10:AJ10),0) -> 16078 | AL10: =IF(AB10<15000,AB10,15000) -> 13306 | AM10: =ROUND(AL10*13%,0) -> 1730 | AN10: =IF(AA10>=21000,0,AK10*3.25%) -> 522.535 | AO10: 5.83 | AP10: =SUM(AM10:AO10) -> 2258.365 | AQ10: =AK10+AP10 -> 18336.365 | AS10: =AQ10+AR10 -> 18336.365 | AT10: =ROUND(AL10*12%,0) -> 1597 | AU10: =IF(AA10>21000,0,CEILING(AK10*0.75%,1)) -> 121 | AV10: 2.5 | AW10: =IF(AK10>20000,200,IF(AK10>15000,150,0)) -> 150 | AX10: =SUM(AT10:AW10) -> 1870.5 | AY10: =ROUND(AK10-AX10,0) -> 14208 | BA10: KAMADENU VENKATA LAXMI | BB10: 1420155000117023 | BC10: KVBL0001420 | BD10: =AY10 -> 14208 | BF10: =ROUND(BD10-BE10,0) -> 14208
A11: 7 | C11: PPRR01063685 | D11: M ANURADHA | E11: MALLA ANURADHA | F11: FEMALE | G11: 102240267440 | H11: 6210707481 | I11: 45887 | J11: ANAKAPALLI | K11: South | L11: Andhra Pradesh | M11: PICKER / PACKER | N11: SemiSkilled | O11: 46054 | P11: 26 | Q11: 27 | R11: 0 | S11: 12813 | T11: 0 | U11: =S11+T11 -> 12813 | V11: 0 | W11: 0 | X11: 0 | Y11: 1602 | Z11: 1067 | AA11: =SUM(U11:Z11) -> 15482 | AB11: =ROUND(S11/P11*Q11,0) -> 13306 | AC11: =ROUND(T11/P11*Q11,0) -> 0 | AD11: =AB11+AC11 -> 13306 | AE11: =ROUND(V11/P11*Q11,0) -> 0 | AF11: =ROUND(W11/P11*Q11,0) -> 0 | AG11: =ROUND(X11/P11*Q11,0) -> 0 | AH11: =ROUND(Y11/P11*Q11,0) -> 1664 | AI11: =ROUND((S11/26)/4*R11,0) -> 0 | AJ11: =ROUND(Z11/P11*Q11,0) -> 1108 | AK11: =ROUND(SUM(AD11:AJ11),0) -> 16078 | AL11: =IF(AB11<15000,AB11,15000) -> 13306 | AM11: =ROUND(AL11*13%,0) -> 1730 | AN11: =IF(AA11>=21000,0,AK11*3.25%) -> 522.535 | AO11: 5.83 | AP11: =SUM(AM11:AO11) -> 2258.365 | AQ11: =AK11+AP11 -> 18336.365 | AS11: =AQ11+AR11 -> 18336.365 | AT11: =ROUND(AL11*12%,0) -> 1597 | AU11: =IF(AA11>21000,0,CEILING(AK11*0.75%,1)) -> 121 | AV11: 2.5 | AW11: =IF(AK11>20000,200,IF(AK11>15000,150,0)) -> 150 | AX11: =SUM(AT11:AW11) -> 1870.5 | AY11: =ROUND(AK11-AX11,0) -> 14208 | BA11: MALLA ANURADHA | BB11: 20304516181 | BC11: SBIN0000805 | BD11: =AY11 -> 14208 | BF11: =ROUND(BD11-BE11,0) -> 14208
A12: 8 | C12: PPRR01064021 | D12: O.ANITHA DEVI | E12: OMMI ANITHADEVI | F12: FEMALE | G12: 102240588465 | H12: 6210708923 | I12: 45895 | J12: ANAKAPALLI | K12: South | L12: Andhra Pradesh | M12: PICKER / PACKER | N12: SemiSkilled | O12: 46054 | P12: 26 | Q12: 20 | R12: 0 | S12: 12813 | T12: 0 | U12: =S12+T12 -> 12813 | V12: 0 | W12: 0 | X12: 0 | Y12: 1602 | Z12: 1067 | AA12: =SUM(U12:Z12) -> 15482 | AB12: =ROUND(S12/P12*Q12,0) -> 9856 | AC12: =ROUND(T12/P12*Q12,0) -> 0 | AD12: =AB12+AC12 -> 9856 | AE12: =ROUND(V12/P12*Q12,0) -> 0 | AF12: =ROUND(W12/P12*Q12,0) -> 0 | AG12: =ROUND(X12/P12*Q12,0) -> 0 | AH12: =ROUND(Y12/P12*Q12,0) -> 1232 | AI12: =ROUND((S12/26)/4*R12,0) -> 0 | AJ12: =ROUND(Z12/P12*Q12,0) -> 821 | AK12: =ROUND(SUM(AD12:AJ12),0) -> 11909 | AL12: =IF(AB12<15000,AB12,15000) -> 9856 | AM12: =ROUND(AL12*13%,0) -> 1281 | AN12: =IF(AA12>=21000,0,AK12*3.25%) -> 387.0425 | AO12: 5.83 | AP12: =SUM(AM12:AO12) -> 1673.8725 | AQ12: =AK12+AP12 -> 13582.872 | AS12: =AQ12+AR12 -> 13582.872 | AT12: =ROUND(AL12*12%,0) -> 1183 | AU12: =IF(AA12>21000,0,CEILING(AK12*0.75%,1)) -> 90 | AV12: 2.5 | AW12: =IF(AK12>20000,200,IF(AK12>15000,150,0)) -> 0 | AX12: =SUM(AT12:AW12) -> 1275.5 | AY12: =ROUND(AK12-AX12,0) -> 10634 | BA12: OMMI ANITHADEVI | BB12: 386602010020426 | BC12: UBIN0538663 | BD12: =AY12 -> 10634 | BF12: =ROUND(BD12-BE12,0) -> 10634
A13: 9 | C13: PPRR01086837 | D13: CHUKKA SUJATHA | E13: CHUKKA SUJATHA | F13: FEMALE | G13: 102243217343 | H13: 6210724683 | I13: 01.09.2025 | J13: ANAKAPALLI | K13: South | L13: Andhra Pradesh | M13: PICKER / PACKER | N13: SemiSkilled | O13: 46054 | P13: 26 | Q13: 28 | R13: 0 | S13: 12813 | T13: 0 | U13: =S13+T13 -> 12813 | V13: 0 | W13: 0 | X13: 0 | Y13: 1602 | Z13: 1067 | AA13: =SUM(U13:Z13) -> 15482 | AB13: =ROUND(S13/P13*Q13,0) -> 13799 | AC13: =ROUND(T13/P13*Q13,0) -> 0 | AD13: =AB13+AC13 -> 13799 | AE13: =ROUND(V13/P13*Q13,0) -> 0 | AF13: =ROUND(W13/P13*Q13,0) -> 0 | AG13: =ROUND(X13/P13*Q13,0) -> 0 | AH13: =ROUND(Y13/P13*Q13,0) -> 1725 | AI13: =ROUND((S13/26)/4*R13,0) -> 0 | AJ13: =ROUND(Z13/P13*Q13,0) -> 1149 | AK13: =ROUND(SUM(AD13:AJ13),0) -> 16673 | AL13: =IF(AB13<15000,AB13,15000) -> 13799 | AM13: =ROUND(AL13*13%,0) -> 1794 | AN13: =IF(AA13>=21000,0,AK13*3.25%) -> 541.8725 | AO13: 5.83 | AP13: =SUM(AM13:AO13) -> 2341.7025 | AQ13: =AK13+AP13 -> 19014.702 | AS13: =AQ13+AR13 -> 19014.702 | AT13: =ROUND(AL13*12%,0) -> 1656 | AU13: =IF(AA13>21000,0,CEILING(AK13*0.75%,1)) -> 126 | AV13: 2.5 | AW13: =IF(AK13>20000,200,IF(AK13>15000,150,0)) -> 150 | AX13: =SUM(AT13:AW13) -> 1934.5 | AY13: =ROUND(AK13-AX13,0) -> 14739 | BA13: CHUKKA SUJATHA | BB13: 36214212666 | BC13: SBIN0000255 | BD13: =AY13 -> 14739 | BF13: =ROUND(BD13-BE13,0) -> 14739
A14: 10 | C14: PPRR01064055 | D14: J SAI KUMAR | E14: JUREDDI SAI KUMAR | F14: MALE | G14: 101619694658 | H14: 5221285007 | I14: 45884 | J14: ANAKAPALLI | K14: South | L14: Andhra Pradesh | M14: PICKER / PACKER | N14: SemiSkilled | O14: 46054 | P14: 26 | Q14: 25 | R14: 0 | S14: 12813 | T14: 0 | U14: =S14+T14 -> 12813 | V14: 0 | W14: 0 | X14: 0 | Y14: 1602 | Z14: 1067 | AA14: =SUM(U14:Z14) -> 15482 | AB14: =ROUND(S14/P14*Q14,0) -> 12320 | AC14: =ROUND(T14/P14*Q14,0) -> 0 | AD14: =AB14+AC14 -> 12320 | AE14: =ROUND(V14/P14*Q14,0) -> 0 | AF14: =ROUND(W14/P14*Q14,0) -> 0 | AG14: =ROUND(X14/P14*Q14,0) -> 0 | AH14: =ROUND(Y14/P14*Q14,0) -> 1540 | AI14: =ROUND((S14/26)/4*R14,0) -> 0 | AJ14: =ROUND(Z14/P14*Q14,0) -> 1026 | AK14: =ROUND(SUM(AD14:AJ14),0) -> 14886 | AL14: =IF(AB14<15000,AB14,15000) -> 12320 | AM14: =ROUND(AL14*13%,0) -> 1602 | AN14: =IF(AA14>=21000,0,AK14*3.25%) -> 483.795 | AO14: 5.83 | AP14: =SUM(AM14:AO14) -> 2091.625 | AQ14: =AK14+AP14 -> 16977.625 | AS14: =AQ14+AR14 -> 16977.625 | AT14: =ROUND(AL14*12%,0) -> 1478 | AU14: =IF(AA14>21000,0,CEILING(AK14*0.75%,1)) -> 112 | AV14: 2.5 | AW14: =IF(AK14>20000,200,IF(AK14>15000,150,0)) -> 0 | AX14: =SUM(AT14:AW14) -> 1592.5 | AY14: =ROUND(AK14-AX14,0) -> 13294 | BA14: J SAI KUMAR | BB14: 44277374213 | BC14: SBIN0000805 | BD14: =AY14 -> 13294 | BF14: =ROUND(BD14-BE14,0) -> 13294
A15: 11 | C15: PPRR01063977 | D15: P.RAMA RAO | E15: POTTU RAMARAO | F15: MALE | G15: 101989390554 | H15: 7011452228 | I15: 45890 | J15: ANAKAPALLI | K15: South | L15: Andhra Pradesh | M15: PICKER / PACKER | N15: SemiSkilled | O15: 46054 | P15: 26 | Q15: 27 | R15: 0 | S15: 12813 | T15: 0 | U15: =S15+T15 -> 12813 | V15: 0 | W15: 0 | X15: 0 | Y15: 1602 | Z15: 1067 | AA15: =SUM(U15:Z15) -> 15482 | AB15: =ROUND(S15/P15*Q15,0) -> 13306 | AC15: =ROUND(T15/P15*Q15,0) -> 0 | AD15: =AB15+AC15 -> 13306 | AE15: =ROUND(V15/P15*Q15,0) -> 0 | AF15: =ROUND(W15/P15*Q15,0) -> 0 | AG15: =ROUND(X15/P15*Q15,0) -> 0 | AH15: =ROUND(Y15/P15*Q15,0) -> 1664 | AI15: =ROUND((S15/26)/4*R15,0) -> 0 | AJ15: =ROUND(Z15/P15*Q15,0) -> 1108 | AK15: =ROUND(SUM(AD15:AJ15),0) -> 16078 | AL15: =IF(AB15<15000,AB15,15000) -> 13306 | AM15: =ROUND(AL15*13%,0) -> 1730 | AN15: =IF(AA15>=21000,0,AK15*3.25%) -> 522.535 | AO15: 5.83 | AP15: =SUM(AM15:AO15) -> 2258.365 | AQ15: =AK15+AP15 -> 18336.365 | AS15: =AQ15+AR15 -> 18336.365 | AT15: =ROUND(AL15*12%,0) -> 1597 | AU15: =IF(AA15>21000,0,CEILING(AK15*0.75%,1)) -> 121 | AV15: 2.5 | AW15: =IF(AK15>20000,200,IF(AK15>15000,150,0)) -> 150 | AX15: =SUM(AT15:AW15) -> 1870.5 | AY15: =ROUND(AK15-AX15,0) -> 14208 | BA15: POTTU RAMARAO | BB15: 8134787836 | BC15: IDIB000M003 | BD15: =AY15 -> 14208 | BF15: =ROUND(BD15-BE15,0) -> 14208
A16: 12 | C16: PPRR01063660 | D16: P.SAI SURENDRA BHANU | E16: PILLI SAI SURENDRA BHANU | F16: MALE | G16: 102227802302 | H16: 6210707392 | I16: 45884 | J16: ANAKAPALLI | K16: South | L16: Andhra Pradesh | M16: PICKER / PACKER | N16: SemiSkilled | O16: 46054 | P16: 26 | Q16: 27 | R16: 0 | S16: 12813 | T16: 0 | U16: =S16+T16 -> 12813 | V16: 0 | W16: 0 | X16: 0 | Y16: 1602 | Z16: 1067 | AA16: =SUM(U16:Z16) -> 15482 | AB16: =ROUND(S16/P16*Q16,0) -> 13306 | AC16: =ROUND(T16/P16*Q16,0) -> 0 | AD16: =AB16+AC16 -> 13306 | AE16: =ROUND(V16/P16*Q16,0) -> 0 | AF16: =ROUND(W16/P16*Q16,0) -> 0 | AG16: =ROUND(X16/P16*Q16,0) -> 0 | AH16: =ROUND(Y16/P16*Q16,0) -> 1664 | AI16: =ROUND((S16/26)/4*R16,0) -> 0 | AJ16: =ROUND(Z16/P16*Q16,0) -> 1108 | AK16: =ROUND(SUM(AD16:AJ16),0) -> 16078 | AL16: =IF(AB16<15000,AB16,15000) -> 13306 | AM16: =ROUND(AL16*13%,0) -> 1730 | AN16: =IF(AA16>=21000,0,AK16*3.25%) -> 522.535 | AO16: 5.83 | AP16: =SUM(AM16:AO16) -> 2258.365 | AQ16: =AK16+AP16 -> 18336.365 | AS16: =AQ16+AR16 -> 18336.365 | AT16: =ROUND(AL16*12%,0) -> 1597 | AU16: =IF(AA16>21000,0,CEILING(AK16*0.75%,1)) -> 121 | AV16: 2.5 | AW16: =IF(AK16>20000,200,IF(AK16>15000,150,0)) -> 150 | AX16: =SUM(AT16:AW16) -> 1870.5 | AY16: =ROUND(AK16-AX16,0) -> 14208 | BA16: PILLI SAI SURENDRA BHANU | BB16: 861210110014493 | BC16: BKID0008612 | BD16: =AY16 -> 14208 | BF16: =ROUND(BD16-BE16,0) -> 14208
A17: 13 | C17: PPRR01086793 | D17: KATTA VAMSI | E17: KATTA VAMSI | F17: MALE | G17: 102248717271 | H17: 6210732036 | I17: 08.09.2025 | J17: ANAKAPALLI | K17: South | L17: Andhra Pradesh | M17: PICKER / PACKER | N17: SemiSkilled | O17: 46054 | P17: 26 | Q17: 26 | R17: 0 | S17: 12813 | T17: 0 | U17: =S17+T17 -> 12813 | V17: 0 | W17: 0 | X17: 0 | Y17: 1602 | Z17: 1067 | AA17: =SUM(U17:Z17) -> 15482 | AB17: =ROUND(S17/P17*Q17,0) -> 12813 | AC17: =ROUND(T17/P17*Q17,0) -> 0 | AD17: =AB17+AC17 -> 12813 | AE17: =ROUND(V17/P17*Q17,0) -> 0 | AF17: =ROUND(W17/P17*Q17,0) -> 0 | AG17: =ROUND(X17/P17*Q17,0) -> 0 | AH17: =ROUND(Y17/P17*Q17,0) -> 1602 | AI17: =ROUND((S17/26)/4*R17,0) -> 0 | AJ17: =ROUND(Z17/P17*Q17,0) -> 1067 | AK17: =ROUND(SUM(AD17:AJ17),0) -> 15482 | AL17: =IF(AB17<15000,AB17,15000) -> 12813 | AM17: =ROUND(AL17*13%,0) -> 1666 | AN17: =IF(AA17>=21000,0,AK17*3.25%) -> 503.165 | AO17: 5.83 | AP17: =SUM(AM17:AO17) -> 2174.995 | AQ17: =AK17+AP17 -> 17656.995 | AS17: =AQ17+AR17 -> 17656.995 | AT17: =ROUND(AL17*12%,0) -> 1538 | AU17: =IF(AA17>21000,0,CEILING(AK17*0.75%,1)) -> 117 | AV17: 2.5 | AW17: =IF(AK17>20000,200,IF(AK17>15000,150,0)) -> 150 | AX17: =SUM(AT17:AW17) -> 1807.5 | AY17: =ROUND(AK17-AX17,0) -> 13675 | BA17: KATTA VAMSI | BB17: 35774062478 | BC17: SBIN0002740 | BD17: =AY17 -> 13675 | BF17: =ROUND(BD17-BE17,0) -> 13675
A18: 14 | C18: PPRR01086755 | D18: MOLLI GANAPATHI KUMAR | E18: MOLLI GANAPATHI KUMAR | F18: MALE | G18: 102248746207 | H18: 6210732026 | I18: 08.09.2025 | J18: ANAKAPALLI | K18: South | L18: Andhra Pradesh | M18: PICKER / PACKER | N18: SemiSkilled | O18: 46054 | P18: 26 | Q18: 27 | R18: 0 | S18: 12813 | T18: 0 | U18: =S18+T18 -> 12813 | V18: 0 | W18: 0 | X18: 0 | Y18: 1602 | Z18: 1067 | AA18: =SUM(U18:Z18) -> 15482 | AB18: =ROUND(S18/P18*Q18,0) -> 13306 | AC18: =ROUND(T18/P18*Q18,0) -> 0 | AD18: =AB18+AC18 -> 13306 | AE18: =ROUND(V18/P18*Q18,0) -> 0 | AF18: =ROUND(W18/P18*Q18,0) -> 0 | AG18: =ROUND(X18/P18*Q18,0) -> 0 | AH18: =ROUND(Y18/P18*Q18,0) -> 1664 | AI18: =ROUND((S18/26)/4*R18,0) -> 0 | AJ18: =ROUND(Z18/P18*Q18,0) -> 1108 | AK18: =ROUND(SUM(AD18:AJ18),0) -> 16078 | AL18: =IF(AB18<15000,AB18,15000) -> 13306 | AM18: =ROUND(AL18*13%,0) -> 1730 | AN18: =IF(AA18>=21000,0,AK18*3.25%) -> 522.535 | AO18: 5.83 | AP18: =SUM(AM18:AO18) -> 2258.365 | AQ18: =AK18+AP18 -> 18336.365 | AS18: =AQ18+AR18 -> 18336.365 | AT18: =ROUND(AL18*12%,0) -> 1597 | AU18: =IF(AA18>21000,0,CEILING(AK18*0.75%,1)) -> 121 | AV18: 2.5 | AW18: =IF(AK18>20000,200,IF(AK18>15000,150,0)) -> 150 | AX18: =SUM(AT18:AW18) -> 1870.5 | AY18: =ROUND(AK18-AX18,0) -> 14208 | BA18: MOLLI GANAPATHI KUMAR | BB18: 37936951472 | BC18: SBIN0002740 | BD18: =AY18 -> 14208 | BF18: =ROUND(BD18-BE18,0) -> 14208
A19: 15 | C19: PPRR01063438 | D19: K CHANDRA KALAVATHI | E19: KUPPALA CHANDRA KALAVATHI | F19: FEMALE | G19: 102104149858 | H19: 6210707229 | I19: 45884 | J19: ANAKAPALLI | K19: South | L19: Andhra Pradesh | M19: PICKER / PACKER | N19: SemiSkilled | O19: 46054 | P19: 26 | Q19: 16 | R19: 0 | S19: 12813 | T19: 0 | U19: =S19+T19 -> 12813 | V19: 0 | W19: 0 | X19: 0 | Y19: 1602 | Z19: 1067 | AA19: =SUM(U19:Z19) -> 15482 | AB19: =ROUND(S19/P19*Q19,0) -> 7885 | AC19: =ROUND(T19/P19*Q19,0) -> 0 | AD19: =AB19+AC19 -> 7885 | AE19: =ROUND(V19/P19*Q19,0) -> 0 | AF19: =ROUND(W19/P19*Q19,0) -> 0 | AG19: =ROUND(X19/P19*Q19,0) -> 0 | AH19: =ROUND(Y19/P19*Q19,0) -> 986 | AI19: =ROUND((S19/26)/4*R19,0) -> 0 | AJ19: =ROUND(Z19/P19*Q19,0) -> 657 | AK19: =ROUND(SUM(AD19:AJ19),0) -> 9528 | AL19: =IF(AB19<15000,AB19,15000) -> 7885 | AM19: =ROUND(AL19*13%,0) -> 1025 | AN19: =IF(AA19>=21000,0,AK19*3.25%) -> 309.66 | AO19: 5.83 | AP19: =SUM(AM19:AO19) -> 1340.49 | AQ19: =AK19+AP19 -> 10868.49 | AS19: =AQ19+AR19 -> 10868.49 | AT19: =ROUND(AL19*12%,0) -> 946 | AU19: =IF(AA19>21000,0,CEILING(AK19*0.75%,1)) -> 72 | AV19: 2.5 | AW19: =IF(AK19>20000,200,IF(AK19>15000,150,0)) -> 0 | AX19: =SUM(AT19:AW19) -> 1020.5 | AY19: =ROUND(AK19-AX19,0) -> 8508 | BA19: KUPPALA CHANDRA KALAVATHI | BB19: 039301000034863 | BC19: IOBA0000393 | BD19: =AY19 -> 8508 | BF19: =ROUND(BD19-BE19,0) -> 8508
P21: =SUM(P5:P20) -> 390 | Q21: =SUM(Q5:Q20) -> 355 | R21: =SUM(R5:R20) -> 0 | S21: =SUM(S5:S20) -> 192195 | T21: =SUM(T5:T20) -> 0 | U21: =SUM(U5:U20) -> 192195 | V21: =SUM(V5:V20) -> 0 | W21: =SUM(W5:W20) -> 0 | ... AY21: =SUM(AY5:AY20) -> 187271 | BD21: =SUM(BD5:BD20) -> 187271 | BE21: =SUM(BE5:BE20) -> 0 | BF21: =SUM(BF5:BF20) -> 187271

Sheet Pay Slips
C2: TECHNO SOLUTIONS
C3: D.NO.6-12-36,12/1 ARUNDEL PET,GUNTUR -522002
C4: Pay Slip for the Month of AUG 2025
D5: Pay Slip Genrated Date: | E5: 44475 | F5: 1
C6: Employee Name | D6: =VLOOKUP($F$5,'Wage Sheet'!$A$4:$AY$20,5,FALSE) -> CHANDAKA SUVARNA LAXMI | E6: Location | F6: =VLOOKUP($F$5,'Wage Sheet'!$A$4:$AY$20,10,FALSE) -> ANAKAPALLI
C7: Designation | D7: =VLOOKUP($F$5,'Wage Sheet'!$A$4:$AY$20,13,FALSE) -> PICKER / PACKER | E7: Month & Year | F7: =VLOOKUP($F$5,'Wage Sheet'!$A$4:$AY$20,15,FALSE) -> 46054
C8: UAN NO | D8: =VLOOKUP($F$5,'Wage Sheet'!$A$4:$AY$20,7,FALSE) -> 101742491826 | E8: ESIC NO | F8: =VLOOKUP($F$5,'Wage Sheet'!$A$4:$AY$20,8,FALSE) -> 7011080364
C9: No Of Days This Month | D9: =VLOOKUP($F$5,'[2]Wage Sheet'!$A$2:$AO$454,13) -> 0 | E9: Days Workerd | F9: =VLOOKUP($F$5,'[2]Wage Sheet'!$A$2:$AO$454,14) -> 922
C11: Earnings | E11: Deductions
C12: Basic-(A) | D12: =VLOOKUP($F$5,'Wage Sheet'!$A$4:$AY$20,31,FALSE) -> 0 | E12: PF (On Basic-A) | F12: =VLOOKUP($F$5,'Wage Sheet'!$A$4:$AY$20,48,FALSE) -> 2.5
C13: HRA-(B) | D13: =VLOOKUP($F$5,'Wage Sheet'!$A$4:$AY$20,32,FALSE) -> 0 | E13: E.S.I.C (On Gross A+B+C+D+E) | F13: =VLOOKUP($F$5,'Wage Sheet'!$A$4:$AY$20,49,FALSE) -> 0
C14: Conveyance-( C ) | D14: =VLOOKUP($F$5,'Wage Sheet'!$A$4:$AY$20,34,FALSE) -> 308 | E14: L W F | F14: =VLOOKUP($F$5,'Wage Sheet'!$A$4:$AY$20,50,FALSE) -> 321.5
C15: BONUS- (D) | D15: =VLOOKUP($F$5,'Wage Sheet'!$A$4:$AY$20,37,FALSE) -> 2977 | E15: Professional Tax | F15: =VLOOKUP($F$5,'Wage Sheet'!$A$4:$AY$20,51,FALSE) -> 2656
C16: PL- ( E) | D16: =VLOOKUP($F$5,'Wage Sheet'!$A$4:$AY$20,35,FALSE) -> 0
C17: Extra Days Payment | D17: =VLOOKUP($F$5,'Wage Sheet'!$A$4:$AY$20,39,FALSE) -> 320
C18: OT Hours Amount | D18: =VLOOKUP($F$5,'Wage Sheet'!$A$4:$AY$20,36,FALSE) -> 205
C19: Total Addition | D19: =SUM(D12:D18) -> 3810 | E19: Total Deduction | F19: =SUM(F12:F18) -> 2980
E20: Net Salary | F20: =(D19-F19) -> 830
C22: Ruppes In words: | D22: {=[3]!SpellNumber(F20)} -> #NAME?
F23: For TECHNO SOLUTIONS
F24: Authorised Signatory
C31: TECHNO SOLUTIONS
C32: D.NO.6-12-36,12/1 ARUNDEL PET,GUNTUR -522002
C33: Pay Slip for the Month of July 2025
D34: Pay Slip Genrated Date: | E34: 44475 | F34: =F5+1 -> 2
C35: Employee Name | D35: =VLOOKUP($F$34,'Wage Sheet'!$A$4:$AY$20,5,FALSE) -> GOVAADA LAVANYA | E35: Location | F35: =VLOOKUP($F$34,'Wage Sheet'!$A$4:$AY$20,10,FALSE) -> ANAKAPALLI
C36: Designation | D36: =VLOOKUP($F$34,'Wage Sheet'!$A$4:$AY$20,13,FALSE) -> PICKER / PACKER | E36: Month & Year | F36: =VLOOKUP($F$34,'Wage Sheet'!$A$4:$AY$20,15,FALSE) -> 46054
C37: UAN NO | D37: =VLOOKUP($F$5,'Wage Sheet'!$A$4:$AY$20,7,FALSE) -> 101742491826 | E37: ESIC NO | F37: =VLOOKUP($F$34,'Wage Sheet'!$A$4:$AY$20,8,FALSE) -> 6210707847
C38: No Of Days This Month | D38: =VLOOKUP($F$34,'[2]Wage Sheet'!$A$2:$AO$454,13) -> 0 | E38: Days Workerd | F38: =VLOOKUP($F$34,'[2]Wage Sheet'!$A$2:$AO$454,14) -> 922
C40: Earnings | E40: Deductions
C41: Basic-(A) | D41: =VLOOKUP($F$34,'Wage Sheet'!$A$4:$AY$20,31,FALSE) -> 0 | E41: PF (On Basic-A) | F41: =VLOOKUP($F$34,'Wage Sheet'!$A$4:$AY$20,48,FALSE) -> 2.5
C42: HRA-(B) | D42: =VLOOKUP($F$34,'Wage Sheet'!$A$4:$AY$20,32,FALSE) -> 0 | E42: E.S.I.C (On Gross A+B+C+D+E) | F42: =VLOOKUP($F$34,'Wage Sheet'!$A$4:$AY$20,49,FALSE) -> 0
C43: Conveyance-( C ) | D43: =VLOOKUP($F$34,'Wage Sheet'!$A$4:$AY$20,34,FALSE) -> 1232 | E43: L W F | F43: =VLOOKUP($F$34,'Wage Sheet'!$A$4:$AY$20,50,FALSE) -> 1275.5
C44: BONUS- (D) | D44: =VLOOKUP($F$34,'Wage Sheet'!$A$4:$AY$20,37,FALSE) -> 11909 | E44: Professional Tax | F44: =VLOOKUP($F$34,'Wage Sheet'!$A$4:$AY$20,51,FALSE) -> 10634
C45: PL- ( E) | D45: =VLOOKUP($F$34,'Wage Sheet'!$A$4:$AY$20,35,FALSE) -> 0
C46: Extra Days Payment | D46: =VLOOKUP($F$34,'Wage Sheet'!$A$4:$AY$20,39,FALSE) -> 1281
C47: Work Incentive | D47: =VLOOKUP($F$34,'Wage Sheet'!$A$4:$AY$20,36,FALSE) -> 821
C48: Total Addition | D48: =SUM(D41:D47) -> 15243 | E48: Total Deduction | F48: =SUM(F41:F47) -> 11912
E49: Net Salary | F49: =(D48-F48) -> 3331
C51: Ruppes In words: | D51: {=[3]!SpellNumber(F49)} -> #NAME?
...

Sheet Invoice
B2: TAX INVOICE
G3: ORIGINAL FOR RECIPIENT
C4: SATHYA GLOBAL STRATEGY
C5: 38-19-10/7A,Jyothi Nagar, Marripalem, Visakhapatnam
C6: GSTIN : 37ADXFS7871B1ZD
C7: PAN : ADXFS7871B
C8: Invoice No : | F8: 6.Invoice Date:
B9: Period of Service from: 21ST APR -2024 TO 20TH MAY -2024
B10: Recipient Name and Address | E10: 7. Check Digit No.
B11: M/s QWIK Supply Chain Pvt Ltd,
B12: C 51 Yard, Plot No. 9, IDA Park, APIIC,, Road No. 8, Vakalpudi,, Thammavaram Village, Kakinada, East Godavari, Andhra Pradesh, 533005
B15: GSTIN : 37AAACF5232A1Z8
B16: PAN : AAACF5232A
B17: SAC : 996729 - Services for Storage/ Warehouse
B18: Place of supply of Service : Nellore / Andhra Pradesh
B19: Sr.No | C19: Description of Services | D19: Quantity | E19: UOM | F19: Rate (Rs.)/UOM | G19: Taxable Value (Rs.)
B20: I. | C20: Services for Storage/ Warehouse | G20: =#REF! -> #REF!
C22: Total Value | G22: =G20 -> #REF!
C25: Central Tax | E25: 9 | F25: % | G25: =+G22*E25% -> #REF!
C26: State Tax | E26: 9 | F26: % | G26: =+G22*E26% -> #REF!
C27: Integrated tax | E27: 0 | F27: % | G27: 0
C28: Union Territory Tax | E28: 0 | F28: % | G28: =+E28*G23% -> 0
C29: Cess | E29: 0 | F29: % | G29: =+E29*G24% -> 0
C31: Total Invoice Value in Rs. 1,95,843/-, In Words …Rupees One Lakh Ninety Five Thusand Eight Hundred Forty Three Only | G31: =ROUND(G22+G25+G26,0) -> #REF!
B32: Forward/reverse charge (Only required for reverse charge) | G32: 0
B34: Customer Purchase Order No. and date .
F35: For SATHYA GLOBAL STRATEGY
B36: Receiver Signature :
F40: Authorised Signature
B42: Principal Place of Business (Supplier) : Hyderabad
B43: Regd.Office : 38-19-10/7A, Jyothi Nagar, Marripalem, Visakhapatnam - 530018 Andhra Pradesh.
B46: The above invoice is to be generated in duplicate :
B47: the original copy to be marked as "ORIGINAL FOR Supplier"
B48: the duplicate copy to be marked as "DUPLICATE FOR Recipient"

Sheet Misc. Invoice
B1: TAX INVOICE
C4: SATHYA GLOBAL STRATEGY
C6: 3rd Floor, Flat No.301, Pratapa's Pride, NGGO'S Colony, Shantipuram, Akkayyapalem, Visakhapatnam, Andhra Pradesh, 530016
B7: TO, | F7: Inv. No. | G7: SGS/24-25/
B8: Reliance Projects & Property Management Services Limited | F8: Inv. Date
B9: C - 51, Plot No. 9, IDA Park, APIIC,, Road No. 8, Vakalpudi, Thammavaram Village, East Godavari, Andhra Pradesh, 533005 | F9: GS.T. NO. | G9: 37ADXFS7871B1ZD
B10: State – Andhra Pradesh | F10: PAN No. | G10: ADXFS7871B
B11: State code - 37
B12: GST No.- 37AAJCR6636B1ZB | F12: SAC Code | G12: 996729
B13: PO No.: 5500271026 | F13: Description | G13: Misc. charges Invoice for the period of 21st December to 20th January'25
B15: Sr. No. | C15: Description | D15: UOM | E15: Qty. | F15: Price | G15: Amount
B17: 1 | C17: Storage & Warehousing Charges for the month of January'25
C18: For the Storage & Warehousing Charges for Reliance Project & Property Management Services Limited
B19: 2 | C19: Management Fees
B20: 3 | C20: Misc. Charges | G20: =#REF! -> #REF!
C25: Sub Total | G25: =SUM(G17:G23) -> #REF!
D26: CGST @ 9% | G26: =G25*9% -> #REF!
D27: SGST @9% | G27: =G26 -> #REF!
D28: IGST @18%
E30: Grand Total | G30: =ROUND(SUM(G25:G28),0) -> #REF!
B31: (Rupees in words…. Eight Hundred Fifty Six Only)
F34: Authorized Signatory

Sheet Left Employee
A1: 45383
A2: Sr. No | B2: Emp code Number ( as allotted by the currnet vendor ) | C2: SCRUM ID | D2: Name as per Attendance | E2: Name of Employee | F2: PF ACCOUNT NUMBERS | G2: UAN NUMBER | H2: ESIC NUMBER | I2: DOJ (MM.DD.YYYY) | J2: Location | K2: Region | L2: State | M2: Designation | N2: Skill Type | O2: No.of days | P2: No.Of.Working Days | Q2: EXTRA DAYS | R2: OT Hrs | S2: Basic | T2: DA | U2: Consolidated Basic/PF Wages | V2: HRA | W2: Other Allownce | X2: Conveyance | Y2: Leave (If payable Monthly) | Z2: Bonus (If payable Monthly) | AA2: Gross Per Month | AB2: Basic | AC2: DA | AD2: Consolidated Basic/PF Wages | AE2: HRA | AF2: Other Allownce | AG2: Conveyance | AH2: Leave (If payable Monthly) | AI2: OT amount | AJ2: Bonus (If payable Monthly) | AK2: Gross Per Month | AL2: EXTRA DAY PAYMENT | AM2: EPF Salary | AN2: PF - 13% | AO2: ESIC - 3.25% | AP2: Employer LWF | AQ2: Total Indirects | AR2: Co Controlling | AS2: Uniform Charges | AT2: CTC | AU2: PF - 12% | AV2: ESIC - 0.75% | AW2: Employee LWF | AX2: PT | AY2: Total Deduction | AZ2: Take Home | BB2: Name of the Acccount Holder | BC2: A/C No. | BD2: IFSC Code | BE2: BANK NAME | BF2: Salary Payable | BG2: Remarks | BH2: Remark2 | BJ2: Uniform (Apron/T-Shirt) | BK2: Colour (Maroon / Sea Green) | BL2: Gender | BM2: Size (S, M, L, XL, XXL) | BN2: Required Quantity | BO2: Issued Quantity | BP2: Balance Quantity | BQ2: Date of Issue | BR2: Size (6,7,8,9,10) | BS2: Required Pairs | BT2: Issued Pairs | BU2: Required Pairs | BV2: Date of Issue | BW2: ID cards | BX2: Issue date | BY2: Appoint letter | BZ2: Issue date
A3: 11 | B3: SGS/RIL/NLR-FC/011 | D3: SOMATHATI DINESH KUMAR | E3: SOMATHATI DINESH KUMAR | F3: GRVSP19631980000017290 | G3: 101731821650 | H3: 7011527236 | I3: 45327 | J3: NELLORE FC | K3: South | L3: Andhra Pradesh | M3: PICKER / PACKER | N3: SemiSkilled | O3: 31 | P3: 0 | Q3: 0 | R3: 0 | S3: 11808 | T3: 0 | U3: =S3+T3 -> 11808 | V3: 281 | W3: 0 | X3: 0 | Y3: 1476 | Z3: 984 | AA3: =SUM(U3:Z3) -> 14549 | AB3: =ROUND(S3/O3*P3,0) -> 0 | AC3: =ROUND(T3/O3*P3,0) -> 0 | AD3: =AB3+AC3 -> 0 | AE3: =ROUND(V3/O3*P3,0) -> 0 | AF3: =ROUND(W3/O3*P3,0) -> 0 | AG3: =ROUND(X3/O3*P3,0) -> 0 | AH3: =ROUND(Y3/O3*P3,0) -> 0 | AI3: =ROUND((S3/26)/4*R3,0) -> 0 | AJ3: =ROUND(Z3/O3*P3,0) -> 0 | AK3: =ROUND(SUM(AD3:AJ3),0) -> 0 | AL3: =ROUND(AA3/O3*Q3,0) -> 0 | AM3: =ROUND(IF(U3>15000,IF(P3<O3,ROUND(15000/O3*P3,0),15000),IF(AD3>U3,U3,AD3)),0) -> 0 | AN3: =ROUND(AM3*13%,0) -> 0 | AO3: =IF(AA3>=21000,0,AK3*3.25%) -> 0 | AP3: 5.83 | AQ3: =SUM(AN3:AP3) -> 5.83 | AR3: =AK3+AQ3 -> 5.83 | AS3: =ROUND(30/O3*P3,0) -> 0 | AT3: =ROUND(AR3+AS3,0) -> 6 | AU3: =ROUND(AM3*12%,0) -> 0 | AV3: =IF(AA3>21000,0,CEILING(AK3*0.75%,1)) -> 0 | AW3: 2.5 | AX3: =IF(AK3>20000,200,IF(AK3>15000,150,0)) -> 0 | AY3: =SUM(AU3:AX3) -> 2.5 | AZ3: =ROUND(AK3-AY3+AL3,0) -> -3 | BB3: SOMATHATI DINESH KUMAR | BC3: 34712210026925 | BD3: CNRB0013471 | BE3: CANARA BANK | BF3: =AZ3 -> -3 | BY3: Yes | BZ3: 19.02.24
A4: 12 | B4: SGS/RIL/NLR-FC/012 | D4: MANNURU KISHORE | E4: MANNURU KISHORE | F4: GRVSP19631980000017292 | G4: 101731905060 | H4: 7011527240 | I4: 45327 | J4: NELLORE FC | K4: South | L4: Andhra Pradesh | M4: PICKER / PACKER | N4: SemiSkilled | O4: 31 | P4: 0 | Q4: 0 | R4: 0 | S4: 11808 | T4: 0 | U4: =S4+T4 -> 11808 | V4: 281 | W4: 0 | X4: 0 | Y4: 1476 | Z4: 984 | AA4: =SUM(U4:Z4) -> 14549 | AB4: =ROUND(S4/O4*P4,0) -> 0 | AC4: =ROUND(T4/O4*P4,0) -> 0 | AD4: =AB4+AC4 -> 0 | AE4: =ROUND(V4/O4*P4,0) -> 0 | AF4: =ROUND(W4/O4*P4,0) -> 0 | AG4: =ROUND(X4/O4*P4,0) -> 0 | AH4: =ROUND(Y4/O4*P4,0) -> 0 | AI4: =ROUND((S4/26)/4*R4,0) -> 0 | AJ4: =ROUND(Z4/O4*P4,0) -> 0 | AK4: =ROUND(SUM(AD4:AJ4),0) -> 0 | AL4: =ROUND(AA4/O4*Q4,0) -> 0 | AM4: =ROUND(IF(U4>15000,IF(P4<O4,ROUND(15000/O4*P4,0),15000),IF(AD4>U4,U4,AD4)),0) -> 0 | AN4: =ROUND(AM4*13%,0) -> 0 | AO4: =IF(AA4>=21000,0,AK4*3.25%) -> 0 | AP4: 5.83 | AQ4: =SUM(AN4:AP4) -> 5.83 | AR4: =AK4+AQ4 -> 5.83 | AS4: =ROUND(30/O4*P4,0) -> 0 | AT4: =ROUND(AR4+AS4,0) -> 6 | AU4: =ROUND(AM4*12%,0) -> 0 | AV4: =IF(AA4>21000,0,CEILING(AK4*0.75%,1)) -> 0 | AW4: 2.5 | AX4: =IF(AK4>20000,200,IF(AK4>15000,150,0)) -> 0 | AY4: =SUM(AU4:AX4) -> 2.5 | AZ4: =ROUND(AK4-AY4+AL4,0) -> -3 | BB4: MANNURU KISHORE | BC4: 62390421953 | BD4: SBIN0015306 | BE4: STATE BANK OF INDIA | BF4: =AZ4 -> -3 | BY4: Yes | BZ4: 19.02.24
A6: June'24 | B6: 21st May to 20th June'24
A7: 6 | B7: SGS/RIL/NLR-FC/006 | D7: OJILI RAJASEKHAR | E7: OJILI RAJASEKHAR | F7: GRVSP19631980000017298 | G7: 101787561552 | H7: 3313661083 | I7: 45327 | J7: NELLORE FC | K7: South | L7: Andhra Pradesh | M7: PICKER / PACKER | N7: SemiSkilled | O7: 31 | P7: 31 | Q7: 0 | R7: 0 | S7: 12339 | T7: 0 | U7: =S7+T7 -> 12339 | V7: 281 | W7: 0 | X7: 0 | Y7: 1542 | Z7: 1028 | AA7: =SUM(U7:Z7) -> 15190 | AB7: =ROUND(S7/O7*P7,0) -> 12339 | AC7: =ROUND(T7/O7*P7,0) -> 0 | AD7: =AB7+AC7 -> 12339 | AE7: =ROUND(V7/O7*P7,0) -> 281 | AF7: =ROUND(W7/O7*P7,0) -> 0 | AG7: =ROUND(X7/O7*P7,0) -> 0 | AH7: =ROUND(Y7/O7*P7,0) -> 1542 | AI7: =ROUND((S7/26)/4*R7,0) -> 0 | AJ7: =ROUND(Z7/O7*P7,0) -> 1028 | AK7: =ROUND(SUM(AD7:AJ7),0) -> 15190 | AL7: =ROUND(AA7/O7*Q7,0) -> 0 | AM7: =ROUND(IF(U7>15000,IF(P7<O7,ROUND(15000/O7*P7,0),15000),IF(AD7>U7,U7,AD7)),0) -> 12339 | AN7: =ROUND(AM7*13%,0) -> 1604 | AO7: =IF(AA7>=21000,0,AK7*3.25%) -> 493.675 | AP7: 5.83 | AQ7: =SUM(AN7:AP7) -> 2103.505 | AR7: =AK7+AQ7 -> 17293.505 | AS7: =ROUND(30/O7*P7,0) -> 30 | AT7: =ROUND(AR7+AS7,0) -> 17324 | AU7: =ROUND(AM7*12%,0) -> 1481 | AV7: =IF(AA7>21000,0,CEILING(AK7*0.75%,1)) -> 114 | AW7: 2.5 | AX7: =IF(AK7>20000,200,IF(AK7>15000,150,0)) -> 150 | AY7: =SUM(AU7:AX7) -> 1747.5 | AZ7: =ROUND(AK7-AY7+AL7,0) -> 13443 | BB7: OJILI RAJASEKHAR | BC7: 33498914194 | BD7: SBIN0007457 | BE7: STATE BANK OF INDIA | BF7: =AZ7 -> 13443 | BY7: Yes | BZ7: 19.02.24
A8: 7 | B8: SGS/RIL/NLR-FC/007 | D8: ARAVA BHARATH | E8: ARAVA BHARATH | F8: GRVSP19631980000017294 | G8: 101932949853 | H8: 7011527212 | I8: 45327 | J8: NELLORE FC | K8: South | L8: Andhra Pradesh | M8: DEO | N8: Skilled | O8: 31 | P8: 31 | Q8: 0 | R8: 0 | S8: 12959 | T8: 0 | U8: =S8+T8 -> 12959 | W8: 0 | X8: 0 | Y8: 1620 | Z8: 1079 | AA8: =SUM(U8:Z8) -> 15658 | AB8: =ROUND(S8/O8*P8,0) -> 12959 | AC8: =ROUND(T8/O8*P8,0) -> 0 | AD8: =AB8+AC8 -> 12959 | AE8: =ROUND(V8/O8*P8,0) -> 0 | AF8: =ROUND(W8/O8*P8,0) -> 0 | AG8: =ROUND(X8/O8*P8,0) -> 0 | AH8: =ROUND(Y8/O8*P8,0) -> 1620 | AI8: =ROUND((S8/26)/4*R8,0) -> 0 | AJ8: =ROUND(Z8/O8*P8,0) -> 1079 | AK8: =ROUND(SUM(AD8:AJ8),0) -> 15658 | AL8: =ROUND(AA8/O8*Q8,0) -> 0 | AM8: =ROUND(IF(U8>15000,IF(P8<O8,ROUND(15000/O8*P8,0),15000),IF(AD8>U8,U8,AD8)),0) -> 12959 | AN8: =ROUND(AM8*13%,0) -> 1685 | AO8: =IF(AA8>=21000,0,AK8*3.25%) -> 508.885 | AP8: 5.83 | AQ8: =SUM(AN8:AP8) -> 2199.715 | AR8: =AK8+AQ8 -> 17857.715 | AS8: =ROUND(30/O8*P8,0) -> 30 | AT8: =ROUND(AR8+AS8,0) -> 17888 | AU8: =ROUND(AM8*12%,0) -> 1555 | AV8: =IF(AA8>21000,0,CEILING(AK8*0.75%,1)) -> 118 | AW8: 2.5 | AX8: =IF(AK8>20000,200,IF(AK8>15000,150,0)) -> 150 | AY8: =SUM(AU8:AX8) -> 1825.5 | AZ8: =ROUND(AK8-AY8+AL8,0) -> 13833 | BB8: ARAVA BHARATH | BC8: 31770075478 | BD8: SBIN0001163 | BE8: STATE BANK OF INDIA | BF8: =AZ8 -> 13833 | BY8: Yes | BZ8: 19.02.24
A9: 9 | B9: SGS/RIL/NLR-FC/009 | D9: BADANAPURI SAIKUMAR | E9: BADANAPURI SAIKUMAR | F9: GRVSP19631980000017291 | G9: 101730545701 | H9: 7011527226 | I9: 45327 | J9: NELLORE FC | K9: South | L9: Andhra Pradesh | M9: PICKER / PACKER | N9: SemiSkilled | O9: 31 | P9: 31 | Q9: 0 | R9: 0 | S9: 12339 | T9: 0 | U9: =S9+T9 -> 12339 | V9: 281 | W9: 0 | X9: 0 | Y9: 1542 | Z9: 1028 | AA9: =SUM(U9:Z9) -> 15190 | AB9: =ROUND(S9/O9*P9,0) -> 12339 | AC9: =ROUND(T9/O9*P9,0) -> 0 | AD9: =AB9+AC9 -> 12339 | AE9: =ROUND(V9/O9*P9,0) -> 281 | AF9: =ROUND(W9/O9*P9,0) -> 0 | AG9: =ROUND(X9/O9*P9,0) -> 0 | AH9: =ROUND(Y9/O9*P9,0) -> 1542 | AI9: =ROUND((S9/26)/4*R9,0) -> 0 | AJ9: =ROUND(Z9/O9*P9,0) -> 1028 | AK9: =ROUND(SUM(AD9:AJ9),0) -> 15190 | AL9: =ROUND(AA9/O9*Q9,0) -> 0 | AM9: =ROUND(IF(U9>15000,IF(P9<O9,ROUND(15000/O9*P9,0),15000),IF(AD9>U9,U9,AD9)),0) -> 12339 | AN9: =ROUND(AM9*13%,0) -> 1604 | AO9: =IF(AA9>=21000,0,AK9*3.25%) -> 493.675 | AP9: 5.83 | AQ9: =SUM(AN9:AP9) -> 2103.505 | AR9: =AK9+AQ9 -> 17293.505 | AS9: =ROUND(30/O9*P9,0) -> 30 | AT9: =ROUND(AR9+AS9,0) -> 17324 | AU9: =ROUND(AM9*12%,0) -> 1481 | AV9: =IF(AA9>21000,0,CEILING(AK9*0.75%,1)) -> 114 | AW9: 2.5 | AX9: =IF(AK9>20000,200,IF(AK9>15000,150,0)) -> 150 | AY9: =SUM(AU9:AX9) -> 1747.5 | AZ9: =ROUND(AK9-AY9+AL9,0) -> 13443 | BB9: BADANAPURI SAIKUMAR | BC9: 8548101008893 | BD9: CNRB0013558 | BE9: CANARA BANK | BF9: =AZ9 -> 13443 | BY9: Yes | BZ9: 19.02.24
A11: July'24 | B11: 21st June to 20th July'24
